Workbook
Name Classification: [1]Lists!$J$2:$J$4
Name Companies: [1]Lists!$B$2:$B$19
Name Disciplinary: [1]Lists!$F$2:$F$7
Name IncidentCategory: [1]Lists!$I$2:$I$4
Name Locations: [1]Lists!$C$2:$C$6
Name Population: [1]Lists!$L$2:$L$3
Name ReportedBy: [1]Lists!$M$2:$M$15
Name Severity: [1]Lists!$K$2:$K$4
Name Status: [1]Lists!$G$2:$G$3
Name TrainingCourse: [1]Lists!$O$2:$O$15
Name TrainingType: [1]Lists!$P$2:$P$3
Name VioCategory: [1]Lists!$D$2:$D$4
Name VioType: [1]Lists!$E$2:$E$19
Name YesNo: [1]Lists!$H$2:$H$3
Name ZoneMetric: [1]Lists!$N$2:$N$15
Name Zones: [1]Lists!$A$2:$A$4

Sheet Main Data
H1: MONTHLY DATA | V1: ROLLING 12 MONTHS | AB1: FREQUENCY
A2: Concerned Month | B2: Manpower | C2: Worked Hours | D2: Nb of Days lost | E2: NM | F2: MRN | G2: FA | H2: RTA | I2: Dangerous Occurance | J2: Property Damage | K2: Severe Accident | L2: MRA | M2: Fatalities | N2: LTA | O2: Total Accidents | P2: Worked Hours - 12M | Q2: Nb of Days lost - 12M | R2: NM - 12M | S2: MRN - 12M | T2: FA - 12M | U2: RTA - 12M | V2: Dangerous Occurance - 12M | W2: Property Damage - 12M | X2: Severe Accident - 12M | Y2: MRA - 12M | Z2: LTA - 12M | AA2: Total Accidents - 12M | AB2: Global Fequency Rate - 12RM | AC2: Frequency Rate - 12RM | AD2: Severity Rate - 12RM
A3: 45658 | B3: 0 | C3: 0 | D3: =SUMIFS('Accident logs'!$K:$K,'Accident logs'!$B:$B,$A3) -> 0 | E3: =COUNTIFS('Accident logs'!$B:$B,$A3,'Accident logs'!$F:$F,"Near Miss") -> 0 | F3: =COUNTIFS('Accident logs'!$B:$B,$A3,'Accident logs'!$M:$M,"MRN") -> 0 | G3: =COUNTIFS('Accident logs'!$B:$B,$A3,'Accident logs'!$F:$F,"First Aid") -> 0 | H3: =COUNTIFS('Accident logs'!$B:$B,$A3,'Accident logs'!$N:$N,"Road Traffic Accident") -> 0 | I3: =COUNTIFS('Accident logs'!$B:$B,$A3,'Accident logs'!$M:$M,"Dangerous Occurance") -> 0 | J3: =COUNTIFS('Accident logs'!$B:$B,$A3,'Accident logs'!$F:$F,"Property Damage") -> 0 | K3: =COUNTIFS('Accident logs'!$B:$B,$A3,'Accident logs'!$F:$F,"Severe Accident") -> 0 | L3: =COUNTIFS('Accident logs'!$B:$B,$A3,'Accident logs'!$M:$M,"MRA") -> 0 | M3: =COUNTIFS('Accident logs'!$B:$B,$A3,'Accident logs'!$N:$N,"Fatality") -> 0 | N3: =COUNTIFS('Accident logs'!$B:$B,$A3,'Accident logs'!$F:$F,"LTA") -> 0 | O3: =$N3+$G3+$K3 -> 0 | P3: =SUMIFS($C:$C,$A:$A,">="&EDATE($A3,-11),$A:$A,"<="&$A3) -> 0 | Q3: =SUMIFS($D:$D,$A:$A,">="&EDATE($A3,-11),$A:$A,"<="&$A3) -> 0 | R3: =SUMIFS($E:$E,$A:$A,">="&EDATE($A3,-11),$A:$A,"<="&$A3) -> 0 | S3: =SUMIFS($F:$F,$A:$A,">="&EDATE($A3,-11),$A:$A,"<="&$A3) -> 0 | T3: =SUMIFS($G:$G,$A:$A,">="&EDATE($A3,-11),$A:$A,"<="&$A3) -> 0 | U3: =SUMIFS($H:$H,$A:$A,">="&EDATE($A3,-11),$A:$A,"<="&$A3) -> 0 | V3: =SUMIFS($I:$I,$A:$A,">="&EDATE($A3,-11),$A:$A,"<="&$A3) -> 0 | W3: =SUMIFS($J:$J,$A:$A,">="&EDATE($A3,-11),$A:$A,"<="&$A3) -> 0 | X3: =SUMIFS($K:$K,$A:$A,">="&EDATE($A3,-11),$A:$A,"<="&$A3) -> 0 | Y3: =SUMIFS($L:$L,$A:$A,">="&EDATE($A3,-11),$A:$A,"<="&$A3) -> 0 | Z3: =SUMIFS($N:$N,$A:$A,">="&EDATE($A3,-11),$A:$A,"<="&$A3) -> 0 | AA3: =$Z3+$T3+$X3 -> 0 | AB3: =IF($P3=0,0,$AA3*1000000/$P3) -> 0 | AC3: =IF($P3=0,0,($Z3+$X3)*1000000/$P3) -> 0 | AD3: =IF($P3=0,0,$Q3*1000/$P3) -> 0
A4: 45689 | B4: 0 | C4: 0 | D4: =SUMIFS('Accident logs'!$K:$K,'Accident logs'!$B:$B,$A4) -> 0 | E4: =COUNTIFS('Accident logs'!$B:$B,$A4,'Accident logs'!$F:$F,"Near Miss") -> 0 | F4: =COUNTIFS('Accident logs'!$B:$B,$A4,'Accident logs'!$M:$M,"MRN") -> 0 | G4: =COUNTIFS('Accident logs'!$B:$B,$A4,'Accident logs'!$F:$F,"First Aid") -> 0 | H4: =COUNTIFS('Accident logs'!$B:$B,$A4,'Accident logs'!$N:$N,"Road Traffic Accident") -> 0 | I4: =COUNTIFS('Accident logs'!$B:$B,$A4,'Accident logs'!$M:$M,"Dangerous Occurance") -> 0 | J4: =COUNTIFS('Accident logs'!$B:$B,$A4,'Accident logs'!$F:$F,"Property Damage") -> 0 | K4: =COUNTIFS('Accident logs'!$B:$B,$A4,'Accident logs'!$F:$F,"Severe Accident") -> 0 | L4: =COUNTIFS('Accident logs'!$B:$B,$A4,'Accident logs'!$M:$M,"MRA") -> 0 | M4: =COUNTIFS('Accident logs'!$B:$B,$A4,'Accident logs'!$N:$N,"Fatality") -> 0 | N4: =COUNTIFS('Accident logs'!$B:$B,$A4,'Accident logs'!$F:$F,"LTA") -> 0 | O4: =$N4+$G4+$K4 -> 0 | P4: =SUMIFS($C:$C,$A:$A,">="&EDATE($A4,-11),$A:$A,"<="&$A4) -> 0 | Q4: =SUMIFS($D:$D,$A:$A,">="&EDATE($A4,-11),$A:$A,"<="&$A4) -> 0 | R4: =SUMIFS($E:$E,$A:$A,">="&EDATE($A4,-11),$A:$A,"<="&$A4) -> 0 | S4: =SUMIFS($F:$F,$A:$A,">="&EDATE($A4,-11),$A:$A,"<="&$A4) -> 0 | T4: =SUMIFS($G:$G,$A:$A,">="&EDATE($A4,-11),$A:$A,"<="&$A4) -> 0 | U4: =SUMIFS($H:$H,$A:$A,">="&EDATE($A4,-11),$A:$A,"<="&$A4) -> 0 | V4: =SUMIFS($I:$I,$A:$A,">="&EDATE($A4,-11),$A:$A,"<="&$A4) -> 0 | W4: =SUMIFS($J:$J,$A:$A,">="&EDATE($A4,-11),$A:$A,"<="&$A4) -> 0 | X4: =SUMIFS($K:$K,$A:$A,">="&EDATE($A4,-11),$A:$A,"<="&$A4) -> 0 | Y4: =SUMIFS($L:$L,$A:$A,">="&EDATE($A4,-11),$A:$A,"<="&$A4) -> 0 | Z4: =SUMIFS($N:$N,$A:$A,">="&EDATE($A4,-11),$A:$A,"<="&$A4) -> 0 | AA4: =$Z4+$T4+$X4 -> 0 | AB4: =IF($P4=0,0,$AA4*1000000/$P4) -> 0 | AC4: =IF($P4=0,0,($Z4+$X4)*1000000/$P4) -> 0 | AD4: =IF($P4=0,0,$Q4*1000/$P4) -> 0
A5: 45717 | B5: 0 | C5: 0 | D5: =SUMIFS('Accident logs'!$K:$K,'Accident logs'!$B:$B,$A5) -> 0 | E5: =COUNTIFS('Accident logs'!$B:$B,$A5,'Accident logs'!$F:$F,"Near Miss") -> 0 | F5: =COUNTIFS('Accident logs'!$B:$B,$A5,'Accident logs'!$M:$M,"MRN") -> 0 | G5: =COUNTIFS('Accident logs'!$B:$B,$A5,'Accident logs'!$F:$F,"First Aid") -> 0 | H5: =COUNTIFS('Accident logs'!$B:$B,$A5,'Accident logs'!$N:$N,"Road Traffic Accident") -> 0 | I5: =COUNTIFS('Accident logs'!$B:$B,$A5,'Accident logs'!$M:$M,"Dangerous Occurance") -> 0 | J5: =COUNTIFS('Accident logs'!$B:$B,$A5,'Accident logs'!$F:$F,"Property Damage") -> 0 | K5: =COUNTIFS('Accident logs'!$B:$B,$A5,'Accident logs'!$F:$F,"Severe Accident") -> 0 | L5: =COUNTIFS('Accident logs'!$B:$B,$A5,'Accident logs'!$M:$M,"MRA") -> 0 | M5: =COUNTIFS('Accident logs'!$B:$B,$A5,'Accident logs'!$N:$N,"Fatality") -> 0 | N5: =COUNTIFS('Accident logs'!$B:$B,$A5,'Accident logs'!$F:$F,"LTA") -> 0 | O5: =$N5+$G5+$K5 -> 0 | P5: =SUMIFS($C:$C,$A:$A,">="&EDATE($A5,-11),$A:$A,"<="&$A5) -> 0 | Q5: =SUMIFS($D:$D,$A:$A,">="&EDATE($A5,-11),$A:$A,"<="&$A5) -> 0 | R5: =SUMIFS($E:$E,$A:$A,">="&EDATE($A5,-11),$A:$A,"<="&$A5) -> 0 | S5: =SUMIFS($F:$F,$A:$A,">="&EDATE($A5,-11),$A:$A,"<="&$A5) -> 0 | T5: =SUMIFS($G:$G,$A:$A,">="&EDATE($A5,-11),$A:$A,"<="&$A5) -> 0 | U5: =SUMIFS($H:$H,$A:$A,">="&EDATE($A5,-11),$A:$A,"<="&$A5) -> 0 | V5: =SUMIFS($I:$I,$A:$A,">="&EDATE($A5,-11),$A:$A,"<="&$A5) -> 0 | W5: =SUMIFS($J:$J,$A:$A,">="&EDATE($A5,-11),$A:$A,"<="&$A5) -> 0 | X5: =SUMIFS($K:$K,$A:$A,">="&EDATE($A5,-11),$A:$A,"<="&$A5) -> 0 | Y5: =SUMIFS($L:$L,$A:$A,">="&EDATE($A5,-11),$A:$A,"<="&$A5) -> 0 | Z5: =SUMIFS($N:$N,$A:$A,">="&EDATE($A5,-11),$A:$A,"<="&$A5) -> 0 | AA5: =$Z5+$T5+$X5 -> 0 | AB5: =IF($P5=0,0,$AA5*1000000/$P5) -> 0 | AC5: =IF($P5=0,0,($Z5+$X5)*1000000/$P5) -> 0 | AD5: =IF($P5=0,0,$Q5*1000/$P5) -> 0
A6: 45748 | B6: 0 | C6: 0 | D6: =SUMIFS('Accident logs'!$K:$K,'Accident logs'!$B:$B,$A6) -> 0 | E6: =COUNTIFS('Accident logs'!$B:$B,$A6,'Accident logs'!$F:$F,"Near Miss") -> 0 | F6: =COUNTIFS('Accident logs'!$B:$B,$A6,'Accident logs'!$M:$M,"MRN") -> 0 | G6: =COUNTIFS('Accident logs'!$B:$B,$A6,'Accident logs'!$F:$F,"First Aid") -> 0 | H6: =COUNTIFS('Accident logs'!$B:$B,$A6,'Accident logs'!$N:$N,"Road Traffic Accident") -> 0 | I6: =COUNTIFS('Accident logs'!$B:$B,$A6,'Accident logs'!$M:$M,"Dangerous Occurance") -> 0 | J6: =COUNTIFS('Accident logs'!$B:$B,$A6,'Accident logs'!$F:$F,"Property Damage") -> 0 | K6: =COUNTIFS('Accident logs'!$B:$B,$A6,'Accident logs'!$F:$F,"Severe Accident") -> 0 | L6: =COUNTIFS('Accident logs'!$B:$B,$A6,'Accident logs'!$M:$M,"MRA") -> 0 | M6: =COUNTIFS('Accident logs'!$B:$B,$A6,'Accident logs'!$N:$N,"Fatality") -> 0 | N6: =COUNTIFS('Accident logs'!$B:$B,$A6,'Accident logs'!$F:$F,"LTA") -> 0 | O6: =$N6+$G6+$K6 -> 0 | P6: =SUMIFS($C:$C,$A:$A,">="&EDATE($A6,-11),$A:$A,"<="&$A6) -> 0 | Q6: =SUMIFS($D:$D,$A:$A,">="&EDATE($A6,-11),$A:$A,"<="&$A6) -> 0 | R6: =SUMIFS($E:$E,$A:$A,">="&EDATE($A6,-11),$A:$A,"<="&$A6) -> 0 | S6: =SUMIFS($F:$F,$A:$A,">="&EDATE($A6,-11),$A:$A,"<="&$A6) -> 0 | T6: =SUMIFS($G:$G,$A:$A,">="&EDATE($A6,-11),$A:$A,"<="&$A6) -> 0 | U6: =SUMIFS($H:$H,$A:$A,">="&EDATE($A6,-11),$A:$A,"<="&$A6) -> 0 | V6: =SUMIFS($I:$I,$A:$A,">="&EDATE($A6,-11),$A:$A,"<="&$A6) -> 0 | W6: =SUMIFS($J:$J,$A:$A,">="&EDATE($A6,-11),$A:$A,"<="&$A6) -> 0 | X6: =SUMIFS($K:$K,$A:$A,">="&EDATE($A6,-11),$A:$A,"<="&$A6) -> 0 | Y6: =SUMIFS($L:$L,$A:$A,">="&EDATE($A6,-11),$A:$A,"<="&$A6) -> 0 | Z6: =SUMIFS($N:$N,$A:$A,">="&EDATE($A6,-11),$A:$A,"<="&$A6) -> 0 | AA6: =$Z6+$T6+$X6 -> 0 | AB6: =IF($P6=0,0,$AA6*1000000/$P6) -> 0 | AC6: =IF($P6=0,0,($Z6+$X6)*1000000/$P6) -> 0 | AD6: =IF($P6=0,0,$Q6*1000/$P6) -> 0
A7: 45778 | B7: 0 | C7: 0 | D7: =SUMIFS('Accident logs'!$K:$K,'Accident logs'!$B:$B,$A7) -> 0 | E7: =COUNTIFS('Accident logs'!$B:$B,$A7,'Accident logs'!$F:$F,"Near Miss") -> 0 | F7: =COUNTIFS('Accident logs'!$B:$B,$A7,'Accident logs'!$M:$M,"MRN") -> 0 | G7: =COUNTIFS('Accident logs'!$B:$B,$A7,'Accident logs'!$F:$F,"First Aid") -> 0 | H7: =COUNTIFS('Accident logs'!$B:$B,$A7,'Accident logs'!$N:$N,"Road Traffic Accident") -> 0 | I7: =COUNTIFS('Accident logs'!$B:$B,$A7,'Accident logs'!$M:$M,"Dangerous Occurance") -> 0 | J7: =COUNTIFS('Accident logs'!$B:$B,$A7,'Accident logs'!$F:$F,"Property Damage") -> 0 | K7: =COUNTIFS('Accident logs'!$B:$B,$A7,'Accident logs'!$F:$F,"Severe Accident") -> 0 | L7: =COUNTIFS('Accident logs'!$B:$B,$A7,'Accident logs'!$M:$M,"MRA") -> 0 | M7: =COUNTIFS('Accident logs'!$B:$B,$A7,'Accident logs'!$N:$N,"Fatality") -> 0 | N7: =COUNTIFS('Accident logs'!$B:$B,$A7,'Accident logs'!$F:$F,"LTA") -> 0 | O7: =$N7+$G7+$K7 -> 0 | P7: =SUMIFS($C:$C,$A:$A,">="&EDATE($A7,-11),$A:$A,"<="&$A7) -> 0 | Q7: =SUMIFS($D:$D,$A:$A,">="&EDATE($A7,-11),$A:$A,"<="&$A7) -> 0 | R7: =SUMIFS($E:$E,$A:$A,">="&EDATE($A7,-11),$A:$A,"<="&$A7) -> 0 | S7: =SUMIFS($F:$F,$A:$A,">="&EDATE($A7,-11),$A:$A,"<="&$A7) -> 0 | T7: =SUMIFS($G:$G,$A:$A,">="&EDATE($A7,-11),$A:$A,"<="&$A7) -> 0 | U7: =SUMIFS($H:$H,$A:$A,">="&EDATE($A7,-11),$A:$A,"<="&$A7) -> 0 | V7: =SUMIFS($I:$I,$A:$A,">="&EDATE($A7,-11),$A:$A,"<="&$A7) -> 0 | W7: =SUMIFS($J:$J,$A:$A,">="&EDATE($A7,-11),$A:$A,"<="&$A7) -> 0 | X7: =SUMIFS($K:$K,$A:$A,">="&EDATE($A7,-11),$A:$A,"<="&$A7) -> 0 | Y7: =SUMIFS($L:$L,$A:$A,">="&EDATE($A7,-11),$A:$A,"<="&$A7) -> 0 | Z7: =SUMIFS($N:$N,$A:$A,">="&EDATE($A7,-11),$A:$A,"<="&$A7) -> 0 | AA7: =$Z7+$T7+$X7 -> 0 | AB7: =IF($P7=0,0,$AA7*1000000/$P7) -> 0 | AC7: =IF($P7=0,0,($Z7+$X7)*1000000/$P7) -> 0 | AD7: =IF($P7=0,0,$Q7*1000/$P7) -> 0
A8: 45809 | B8: 0 | C8: 0 | D8: =SUMIFS('Accident logs'!$K:$K,'Accident logs'!$B:$B,$A8) -> 0 | E8: =COUNTIFS('Accident logs'!$B:$B,$A8,'Accident logs'!$F:$F,"Near Miss") -> 0 | F8: =COUNTIFS('Accident logs'!$B:$B,$A8,'Accident logs'!$M:$M,"MRN") -> 0 | G8: =COUNTIFS('Accident logs'!$B:$B,$A8,'Accident logs'!$F:$F,"First Aid") -> 0 | H8: =COUNTIFS('Accident logs'!$B:$B,$A8,'Accident logs'!$N:$N,"Road Traffic Accident") -> 0 | I8: =COUNTIFS('Accident logs'!$B:$B,$A8,'Accident logs'!$M:$M,"Dangerous Occurance") -> 0 | J8: =COUNTIFS('Accident logs'!$B:$B,$A8,'Accident logs'!$F:$F,"Property Damage") -> 0 | K8: =COUNTIFS('Accident logs'!$B:$B,$A8,'Accident logs'!$F:$F,"Severe Accident") -> 0 | L8: =COUNTIFS('Accident logs'!$B:$B,$A8,'Accident logs'!$M:$M,"MRA") -> 0 | M8: =COUNTIFS('Accident logs'!$B:$B,$A8,'Accident logs'!$N:$N,"Fatality") -> 0 | N8: =COUNTIFS('Accident logs'!$B:$B,$A8,'Accident logs'!$F:$F,"LTA") -> 0 | O8: =$N8+$G8+$K8 -> 0 | P8: =SUMIFS($C:$C,$A:$A,">="&EDATE($A8,-11),$A:$A,"<="&$A8) -> 0 | Q8: =SUMIFS($D:$D,$A:$A,">="&EDATE($A8,-11),$A:$A,"<="&$A8) -> 0 | R8: =SUMIFS($E:$E,$A:$A,">="&EDATE($A8,-11),$A:$A,"<="&$A8) -> 0 | S8: =SUMIFS($F:$F,$A:$A,">="&EDATE($A8,-11),$A:$A,"<="&$A8) -> 0 | T8: =SUMIFS($G:$G,$A:$A,">="&EDATE($A8,-11),$A:$A,"<="&$A8) -> 0 | U8: =SUMIFS($H:$H,$A:$A,">="&EDATE($A8,-11),$A:$A,"<="&$A8) -> 0 | V8: =SUMIFS($I:$I,$A:$A,">="&EDATE($A8,-11),$A:$A,"<="&$A8) -> 0 | W8: =SUMIFS($J:$J,$A:$A,">="&EDATE($A8,-11),$A:$A,"<="&$A8) -> 0 | X8: =SUMIFS($K:$K,$A:$A,">="&EDATE($A8,-11),$A:$A,"<="&$A8) -> 0 | Y8: =SUMIFS($L:$L,$A:$A,">="&EDATE($A8,-11),$A:$A,"<="&$A8) -> 0 | Z8: =SUMIFS($N:$N,$A:$A,">="&EDATE($A8,-11),$A:$A,"<="&$A8) -> 0 | AA8: =$Z8+$T8+$X8 -> 0 | AB8: =IF($P8=0,0,$AA8*1000000/$P8) -> 0 | AC8: =IF($P8=0,0,($Z8+$X8)*1000000/$P8) -> 0 | AD8: =IF($P8=0,0,$Q8*1000/$P8) -> 0
A9: 45839 | B9: 0 | C9: 0 | D9: =SUMIFS('Accident logs'!$K:$K,'Accident logs'!$B:$B,$A9) -> 0 | E9: =COUNTIFS('Accident logs'!$B:$B,$A9,'Accident logs'!$F:$F,"Near Miss") -> 0 | F9: =COUNTIFS('Accident logs'!$B:$B,$A9,'Accident logs'!$M:$M,"MRN") -> 0 | G9: =COUNTIFS('Accident logs'!$B:$B,$A9,'Accident logs'!$F:$F,"First Aid") -> 0 | H9: =COUNTIFS('Accident logs'!$B:$B,$A9,'Accident logs'!$N:$N,"Road Traffic Accident") -> 0 | I9: =COUNTIFS('Accident logs'!$B:$B,$A9,'Accident logs'!$M:$M,"Dangerous Occurance") -> 0 | J9: =COUNTIFS('Accident logs'!$B:$B,$A9,'Accident logs'!$F:$F,"Property Damage") -> 0 | K9: =COUNTIFS('Accident logs'!$B:$B,$A9,'Accident logs'!$F:$F,"Severe Accident") -> 0 | L9: =COUNTIFS('Accident logs'!$B:$B,$A9,'Accident logs'!$M:$M,"MRA") -> 0 | M9: =COUNTIFS('Accident logs'!$B:$B,$A9,'Accident logs'!$N:$N,"Fatality") -> 0 | N9: =COUNTIFS('Accident logs'!$B:$B,$A9,'Accident logs'!$F:$F,"LTA") -> 0 | O9: =$N9+$G9+$K9 -> 0 | P9: =SUMIFS($C:$C,$A:$A,">="&EDATE($A9,-11),$A:$A,"<="&$A9) -> 0 | Q9: =SUMIFS($D:$D,$A:$A,">="&EDATE($A9,-11),$A:$A,"<="&$A9) -> 0 | R9: =SUMIFS($E:$E,$A:$A,">="&EDATE($A9,-11),$A:$A,"<="&$A9) -> 0 | S9: =SUMIFS($F:$F,$A:$A,">="&EDATE($A9,-11),$A:$A,"<="&$A9) -> 0 | T9: =SUMIFS($G:$G,$A:$A,">="&EDATE($A9,-11),$A:$A,"<="&$A9) -> 0 | U9: =SUMIFS($H:$H,$A:$A,">="&EDATE($A9,-11),$A:$A,"<="&$A9) -> 0 | V9: =SUMIFS($I:$I,$A:$A,">="&EDATE($A9,-11),$A:$A,"<="&$A9) -> 0 | W9: =SUMIFS($J:$J,$A:$A,">="&EDATE($A9,-11),$A:$A,"<="&$A9) -> 0 | X9: =SUMIFS($K:$K,$A:$A,">="&EDATE($A9,-11),$A:$A,"<="&$A9) -> 0 | Y9: =SUMIFS($L:$L,$A:$A,">="&EDATE($A9,-11),$A:$A,"<="&$A9) -> 0 | Z9: =SUMIFS($N:$N,$A:$A,">="&EDATE($A9,-11),$A:$A,"<="&$A9) -> 0 | AA9: =$Z9+$T9+$X9 -> 0 | AB9: =IF($P9=0,0,$AA9*1000000/$P9) -> 0 | AC9: =IF($P9=0,0,($Z9+$X9)*1000000/$P9) -> 0 | AD9: =IF($P9=0,0,$Q9*1000/$P9) -> 0
A10: 45870 | B10: 0 | C10: 0 | D10: =SUMIFS('Accident logs'!$K:$K,'Accident logs'!$B:$B,$A10) -> 0 | E10: =COUNTIFS('Accident logs'!$B:$B,$A10,'Accident logs'!$F:$F,"Near Miss") -> 0 | F10: =COUNTIFS('Accident logs'!$B:$B,$A10,'Accident logs'!$M:$M,"MRN") -> 0 | G10: =COUNTIFS('Accident logs'!$B:$B,$A10,'Accident logs'!$F:$F,"First Aid") -> 0 | H10: =COUNTIFS('Accident logs'!$B:$B,$A10,'Accident logs'!$N:$N,"Road Traffic Accident") -> 0 | I10: =COUNTIFS('Accident logs'!$B:$B,$A10,'Accident logs'!$M:$M,"Dangerous Occurance") -> 0 | J10: =COUNTIFS('Accident logs'!$B:$B,$A10,'Accident logs'!$F:$F,"Property Damage") -> 0 | K10: =COUNTIFS('Accident logs'!$B:$B,$A10,'Accident logs'!$F:$F,"Severe Accident") -> 0 | L10: =COUNTIFS('Accident logs'!$B:$B,$A10,'Accident logs'!$M:$M,"MRA") -> 0 | M10: =COUNTIFS('Accident logs'!$B:$B,$A10,'Accident logs'!$N:$N,"Fatality") -> 0 | N10: =COUNTIFS('Accident logs'!$B:$B,$A10,'Accident logs'!$F:$F,"LTA") -> 0 | O10: =$N10+$G10+$K10 -> 0 | P10: =SUMIFS($C:$C,$A:$A,">="&EDATE($A10,-11),$A:$A,"<="&$A10) -> 0 | Q10: =SUMIFS($D:$D,$A:$A,">="&EDATE($A10,-11),$A:$A,"<="&$A10) -> 0 | R10: =SUMIFS($E:$E,$A:$A,">="&EDATE($A10,-11),$A:$A,"<="&$A10) -> 0 | S10: =SUMIFS($F:$F,$A:$A,">="&EDATE($A10,-11),$A:$A,"<="&$A10) -> 0 | T10: =SUMIFS($G:$G,$A:$A,">="&EDATE($A10,-11),$A:$A,"<="&$A10) -> 0 | U10: =SUMIFS($H:$H,$A:$A,">="&EDATE($A10,-11),$A:$A,"<="&$A10) -> 0 | V10: =SUMIFS($I:$I,$A:$A,">="&EDATE($A10,-11),$A:$A,"<="&$A10) -> 0 | W10: =SUMIFS($J:$J,$A:$A,">="&EDATE($A10,-11),$A:$A,"<="&$A10) -> 0 | X10: =SUMIFS($K:$K,$A:$A,">="&EDATE($A10,-11),$A:$A,"<="&$A10) -> 0 | Y10: =SUMIFS($L:$L,$A:$A,">="&EDATE($A10,-11),$A:$A,"<="&$A10) -> 0 | Z10: =SUMIFS($N:$N,$A:$A,">="&EDATE($A10,-11),$A:$A,"<="&$A10) -> 0 | AA10: =$Z10+$T10+$X10 -> 0 | AB10: =IF($P10=0,0,$AA10*1000000/$P10) -> 0 | AC10: =IF($P10=0,0,($Z10+$X10)*1000000/$P10) -> 0 | AD10: =IF($P10=0,0,$Q10*1000/$P10) -> 0
A11: 45901 | B11: 0 | C11: 0 | D11: =SUMIFS('Accident logs'!$K:$K,'Accident logs'!$B:$B,$A11) -> 0 | E11: =COUNTIFS('Accident logs'!$B:$B,$A11,'Accident logs'!$F:$F,"Near Miss") -> 0 | F11: =COUNTIFS('Accident logs'!$B:$B,$A11,'Accident logs'!$M:$M,"MRN") -> 0 | G11: =COUNTIFS('Accident logs'!$B:$B,$A11,'Accident logs'!$F:$F,"First Aid") -> 0 | H11: =COUNTIFS('Accident logs'!$B:$B,$A11,'Accident logs'!$N:$N,"Road Traffic Accident") -> 0 | I11: =COUNTIFS('Accident logs'!$B:$B,$A11,'Accident logs'!$M:$M,"Dangerous Occurance") -> 0 | J11: =COUNTIFS('Accident logs'!$B:$B,$A11,'Accident logs'!$F:$F,"Property Damage") -> 0 | K11: =COUNTIFS('Accident logs'!$B:$B,$A11,'Accident logs'!$F:$F,"Severe Accident") -> 0 | L11: =COUNTIFS('Accident logs'!$B:$B,$A11,'Accident logs'!$M:$M,"MRA") -> 0 | M11: =COUNTIFS('Accident logs'!$B:$B,$A11,'Accident logs'!$N:$N,"Fatality") -> 0 | N11: =COUNTIFS('Accident logs'!$B:$B,$A11,'Accident logs'!$F:$F,"LTA") -> 0 | O11: =$N11+$G11+$K11 -> 0 | P11: =SUMIFS($C:$C,$A:$A,">="&EDATE($A11,-11),$A:$A,"<="&$A11) -> 0 | Q11: =SUMIFS($D:$D,$A:$A,">="&EDATE($A11,-11),$A:$A,"<="&$A11) -> 0 | R11: =SUMIFS($E:$E,$A:$A,">="&EDATE($A11,-11),$A:$A,"<="&$A11) -> 0 | S11: =SUMIFS($F:$F,$A:$A,">="&EDATE($A11,-11),$A:$A,"<="&$A11) -> 0 | T11: =SUMIFS($G:$G,$A:$A,">="&EDATE($A11,-11),$A:$A,"<="&$A11) -> 0 | U11: =SUMIFS($H:$H,$A:$A,">="&EDATE($A11,-11),$A:$A,"<="&$A11) -> 0 | V11: =SUMIFS($I:$I,$A:$A,">="&EDATE($A11,-11),$A:$A,"<="&$A11) -> 0 | W11: =SUMIFS($J:$J,$A:$A,">="&EDATE($A11,-11),$A:$A,"<="&$A11) -> 0 | X11: =SUMIFS($K:$K,$A:$A,">="&EDATE($A11,-11),$A:$A,"<="&$A11) -> 0 | Y11: =SUMIFS($L:$L,$A:$A,">="&EDATE($A11,-11),$A:$A,"<="&$A11) -> 0 | Z11: =SUMIFS($N:$N,$A:$A,">="&EDATE($A11,-11),$A:$A,"<="&$A11) -> 0 | AA11: =$Z11+$T11+$X11 -> 0 | AB11: =IF($P11=0,0,$AA11*1000000/$P11) -> 0 | AC11: =IF($P11=0,0,($Z11+$X11)*1000000/$P11) -> 0 | AD11: =IF($P11=0,0,$Q11*1000/$P11) -> 0
A12: 45931 | B12: 147 | C12: 38220 | D12: =SUMIFS('Accident logs'!$K:$K,'Accident logs'!$B:$B,$A12) -> 0 | E12: =COUNTIFS('Accident logs'!$B:$B,$A12,'Accident logs'!$F:$F,"Near Miss") -> 0 | F12: =COUNTIFS('Accident logs'!$B:$B,$A12,'Accident logs'!$M:$M,"MRN") -> 0 | G12: =COUNTIFS('Accident logs'!$B:$B,$A12,'Accident logs'!$F:$F,"First Aid") -> 0 | H12: =COUNTIFS('Accident logs'!$B:$B,$A12,'Accident logs'!$N:$N,"Road Traffic Accident") -> 0 | I12: =COUNTIFS('Accident logs'!$B:$B,$A12,'Accident logs'!$M:$M,"Dangerous Occurance") -> 0 | J12: =COUNTIFS('Accident logs'!$B:$B,$A12,'Accident logs'!$F:$F,"Property Damage") -> 0 | K12: =COUNTIFS('Accident logs'!$B:$B,$A12,'Accident logs'!$F:$F,"Severe Accident") -> 0 | L12: =COUNTIFS('Accident logs'!$B:$B,$A12,'Accident logs'!$M:$M,"MRA") -> 0 | M12: =COUNTIFS('Accident logs'!$B:$B,$A12,'Accident logs'!$N:$N,"Fatality") -> 0 | N12: =COUNTIFS('Accident logs'!$B:$B,$A12,'Accident logs'!$F:$F,"LTA") -> 0 | O12: =$N12+$G12+$K12 -> 0 | P12: =SUMIFS($C:$C,$A:$A,">="&EDATE($A12,-11),$A:$A,"<="&$A12) -> 38220 | Q12: =SUMIFS($D:$D,$A:$A,">="&EDATE($A12,-11),$A:$A,"<="&$A12) -> 0 | R12: =SUMIFS($E:$E,$A:$A,">="&EDATE($A12,-11),$A:$A,"<="&$A12) -> 0 | S12: =SUMIFS($F:$F,$A:$A,">="&EDATE($A12,-11),$A:$A,"<="&$A12) -> 0 | T12: =SUMIFS($G:$G,$A:$A,">="&EDATE($A12,-11),$A:$A,"<="&$A12) -> 0 | U12: =SUMIFS($H:$H,$A:$A,">="&EDATE($A12,-11),$A:$A,"<="&$A12) -> 0 | V12: =SUMIFS($I:$I,$A:$A,">="&EDATE($A12,-11),$A:$A,"<="&$A12) -> 0 | W12: =SUMIFS($J:$J,$A:$A,">="&EDATE($A12,-11),$A:$A,"<="&$A12) -> 0 | X12: =SUMIFS($K:$K,$A:$A,">="&EDATE($A12,-11),$A:$A,"<="&$A12) -> 0 | Y12: =SUMIFS($L:$L,$A:$A,">="&EDATE($A12,-11),$A:$A,"<="&$A12) -> 0 | Z12: =SUMIFS($N:$N,$A:$A,">="&EDATE($A12,-11),$A:$A,"<="&$A12) -> 0 | AA12: =$Z12+$T12+$X12 -> 0 | AB12: =IF($P12=0,0,$AA12*1000000/$P12) -> 0 | AC12: =IF($P12=0,0,($Z12+$X12)*1000000/$P12) -> 0 | AD12: =IF($P12=0,0,$Q12*1000/$P12) -> 0
A13: 45962 | B13: 347 | C13: 64440 | D13: =SUMIFS('Accident logs'!$K:$K,'Accident logs'!$B:$B,$A13) -> 0 | E13: =COUNTIFS('Accident logs'!$B:$B,$A13,'Accident logs'!$F:$F,"Near Miss") -> 0 | F13: =COUNTIFS('Accident logs'!$B:$B,$A13,'Accident logs'!$M:$M,"MRN") -> 0 | G13: =COUNTIFS('Accident logs'!$B:$B,$A13,'Accident logs'!$F:$F,"First Aid") -> 0 | H13: =COUNTIFS('Accident logs'!$B:$B,$A13,'Accident logs'!$N:$N,"Road Traffic Accident") -> 0 | I13: =COUNTIFS('Accident logs'!$B:$B,$A13,'Accident logs'!$M:$M,"Dangerous Occurance") -> 0 | J13: =COUNTIFS('Accident logs'!$B:$B,$A13,'Accident logs'!$F:$F,"Property Damage") -> 0 | K13: =COUNTIFS('Accident logs'!$B:$B,$A13,'Accident logs'!$F:$F,"Severe Accident") -> 0 | L13: =COUNTIFS('Accident logs'!$B:$B,$A13,'Accident logs'!$M:$M,"MRA") -> 0 | M13: =COUNTIFS('Accident logs'!$B:$B,$A13,'Accident logs'!$N:$N,"Fatality") -> 0 | N13: =COUNTIFS('Accident logs'!$B:$B,$A13,'Accident logs'!$F:$F,"LTA") -> 0 | O13: =$N13+$G13+$K13 -> 0 | P13: =SUMIFS($C:$C,$A:$A,">="&EDATE($A13,-11),$A:$A,"<="&$A13) -> 102660 | Q13: =SUMIFS($D:$D,$A:$A,">="&EDATE($A13,-11),$A:$A,"<="&$A13) -> 0 | R13: =SUMIFS($E:$E,$A:$A,">="&EDATE($A13,-11),$A:$A,"<="&$A13) -> 0 | S13: =SUMIFS($F:$F,$A:$A,">="&EDATE($A13,-11),$A:$A,"<="&$A13) -> 0 | T13: =SUMIFS($G:$G,$A:$A,">="&EDATE($A13,-11),$A:$A,"<="&$A13) -> 0 | U13: =SUMIFS($H:$H,$A:$A,">="&EDATE($A13,-11),$A:$A,"<="&$A13) -> 0 | V13: =SUMIFS($I:$I,$A:$A,">="&EDATE($A13,-11),$A:$A,"<="&$A13) -> 0 | W13: =SUMIFS($J:$J,$A:$A,">="&EDATE($A13,-11),$A:$A,"<="&$A13) -> 0 | X13: =SUMIFS($K:$K,$A:$A,">="&EDATE($A13,-11),$A:$A,"<="&$A13) -> 0 | Y13: =SUMIFS($L:$L,$A:$A,">="&EDATE($A13,-11),$A:$A,"<="&$A13) -> 0 | Z13: =SUMIFS($N:$N,$A:$A,">="&EDATE($A13,-11),$A:$A,"<="&$A13) -> 0 | AA13: =$Z13+$T13+$X13 -> 0 | AB13: =IF($P13=0,0,$AA13*1000000/$P13) -> 0 | AC13: =IF($P13=0,0,($Z13+$X13)*1000000/$P13) -> 0 | AD13: =IF($P13=0,0,$Q13*1000/$P13) -> 0
A14: 45992 | B14: 478 | C14: 138960 | D14: =SUMIFS('Accident logs'!$K:$K,'Accident logs'!$B:$B,$A14) -> 0 | E14: =COUNTIFS('Accident logs'!$B:$B,$A14,'Accident logs'!$F:$F,"Near Miss") -> 1 | F14: =COUNTIFS('Accident logs'!$B:$B,$A14,'Accident logs'!$M:$M,"MRN") -> 1 | G14: =COUNTIFS('Accident logs'!$B:$B,$A14,'Accident logs'!$F:$F,"First Aid") -> 1 | H14: =COUNTIFS('Accident logs'!$B:$B,$A14,'Accident logs'!$N:$N,"Road Traffic Accident") -> 0 | I14: =COUNTIFS('Accident logs'!$B:$B,$A14,'Accident logs'!$M:$M,"Dangerous Occurance") -> 0 | J14: =COUNTIFS('Accident logs'!$B:$B,$A14,'Accident logs'!$F:$F,"Property Damage") -> 0 | K14: =COUNTIFS('Accident logs'!$B:$B,$A14,'Accident logs'!$F:$F,"Severe Accident") -> 0 | L14: =COUNTIFS('Accident logs'!$B:$B,$A14,'Accident logs'!$M:$M,"MRA") -> 0 | M14: =COUNTIFS('Accident logs'!$B:$B,$A14,'Accident logs'!$N:$N,"Fatality") -> 0 | N14: =COUNTIFS('Accident logs'!$B:$B,$A14,'Accident logs'!$F:$F,"LTA") -> 0 | O14: =$N14+$G14+$K14 -> 1 | P14: =SUMIFS($C:$C,$A:$A,">="&EDATE($A14,-11),$A:$A,"<="&$A14) -> 241620 | Q14: =SUMIFS($D:$D,$A:$A,">="&EDATE($A14,-11),$A:$A,"<="&$A14) -> 0 | R14: =SUMIFS($E:$E,$A:$A,">="&EDATE($A14,-11),$A:$A,"<="&$A14) -> 1 | S14: =SUMIFS($F:$F,$A:$A,">="&EDATE($A14,-11),$A:$A,"<="&$A14) -> 1 | T14: =SUMIFS($G:$G,$A:$A,">="&EDATE($A14,-11),$A:$A,"<="&$A14) -> 1 | U14: =SUMIFS($H:$H,$A:$A,">="&EDATE($A14,-11),$A:$A,"<="&$A14) -> 0 | V14: =SUMIFS($I:$I,$A:$A,">="&EDATE($A14,-11),$A:$A,"<="&$A14) -> 0 | W14: =SUMIFS($J:$J,$A:$A,">="&EDATE($A14,-11),$A:$A,"<="&$A14) -> 0 | X14: =SUMIFS($K:$K,$A:$A,">="&EDATE($A14,-11),$A:$A,"<="&$A14) -> 0 | Y14: =SUMIFS($L:$L,$A:$A,">="&EDATE($A14,-11),$A:$A,"<="&$A14) -> 0 | Z14: =SUMIFS($N:$N,$A:$A,">="&EDATE($A14,-11),$A:$A,"<="&$A14) -> 0 | AA14: =$Z14+$T14+$X14 -> 1 | AB14: =IF($P14=0,0,$AA14*1000000/$P14) -> 4.1387302 | AC14: =IF($P14=0,0,($Z14+$X14)*1000000/$P14) -> 0 | AD14: =IF($P14=0,0,$Q14*1000/$P14) -> 0
... A20: 46174 | B20: 1046 | C20: 127320 | D20: =SUMIFS('Accident logs'!$K:$K,'Accident logs'!$B:$B,$A20) -> 0 | E20: =COUNTIFS('Accident logs'!$B:$B,$A20,'Accident logs'!$F:$F,"Near Miss") -> 0 | F20: =COUNTIFS('Accident logs'!$B:$B,$A20,'Accident logs'!$M:$M,"MRN") -> 0 | G20: =COUNTIFS('Accident logs'!$B:$B,$A20,'Accident logs'!$F:$F,"First Aid") -> 2 | H20: =COUNTIFS('Accident logs'!$B:$B,$A20,'Accident logs'!$N:$N,"Road Traffic Accident") -> 0 | I20: =COUNTIFS('Accident logs'!$B:$B,$A20,'Accident logs'!$M:$M,"Dangerous Occurance") -> 0 | J20: =COUNTIFS('Accident logs'!$B:$B,$A20,'Accident logs'!$F:$F,"Property Damage") -> 0 | K20: =COUNTIFS('Accident logs'!$B:$B,$A20,'Accident logs'!$F:$F,"Severe Accident") -> 0 | L20: =COUNTIFS('Accident logs'!$B:$B,$A20,'Accident logs'!$M:$M,"MRA") -> 0 | M20: =COUNTIFS('Accident logs'!$B:$B,$A20,'Accident logs'!$N:$N,"Fatality") -> 0 | N20: =COUNTIFS('Accident logs'!$B:$B,$A20,'Accident logs'!$F:$F,"LTA") -> 0 | O20: =$N20+$G20+$K20 -> 2 | P20: =SUMIFS($C:$C,$A:$A,">="&EDATE($A20,-11),$A:$A,"<="&$A20) -> 1391310 | Q20: =SUMIFS($D:$D,$A:$A,">="&EDATE($A20,-11),$A:$A,"<="&$A20) -> 0 | R20: =SUMIFS($E:$E,$A:$A,">="&EDATE($A20,-11),$A:$A,"<="&$A20) -> 13 | S20: =SUMIFS($F:$F,$A:$A,">="&EDATE($A20,-11),$A:$A,"<="&$A20) -> 9 | T20: =SUMIFS($G:$G,$A:$A,">="&EDATE($A20,-11),$A:$A,"<="&$A20) -> 10 | U20: =SUMIFS($H:$H,$A:$A,">="&EDATE($A20,-11),$A:$A,"<="&$A20) -> 0 | V20: =SUMIFS($I:$I,$A:$A,">="&EDATE($A20,-11),$A:$A,"<="&$A20) -> 0 | W20: =SUMIFS($J:$J,$A:$A,">="&EDATE($A20,-11),$A:$A,"<="&$A20) -> 0 | X20: =SUMIFS($K:$K,$A:$A,">="&EDATE($A20,-11),$A:$A,"<="&$A20) -> 1 | Y20: =SUMIFS($L:$L,$A:$A,">="&EDATE($A20,-11),$A:$A,"<="&$A20) -> 1 | Z20: =SUMIFS($N:$N,$A:$A,">="&EDATE($A20,-11),$A:$A,"<="&$A20) -> 0 | AA20: =$Z20+$T20+$X20 -> 11 | AB20: =IF($P20=0,0,$AA20*1000000/$P20) -> 7.9062179 | AC20: =IF($P20=0,0,($Z20+$X20)*1000000/$P20) -> 0.71874708 | AD20: =IF($P20=0,0,$Q20*1000/$P20) -> 0
A21: 46204 | D21: =SUMIFS('Accident logs'!$K:$K,'Accident logs'!$B:$B,$A21) -> 0 | E21: =COUNTIFS('Accident logs'!$B:$B,$A21,'Accident logs'!$F:$F,"Near Miss") -> 0 | F21: =COUNTIFS('Accident logs'!$B:$B,$A21,'Accident logs'!$M:$M,"MRN") -> 0 | G21: =COUNTIFS('Accident logs'!$B:$B,$A21,'Accident logs'!$F:$F,"First Aid") -> 0 | H21: =COUNTIFS('Accident logs'!$B:$B,$A21,'Accident logs'!$N:$N,"Road Traffic Accident") -> 0 | I21: =COUNTIFS('Accident logs'!$B:$B,$A21,'Accident logs'!$M:$M,"Dangerous Occurance") -> 0 | J21: =COUNTIFS('Accident logs'!$B:$B,$A21,'Accident logs'!$F:$F,"Property Damage") -> 0 | K21: =COUNTIFS('Accident logs'!$B:$B,$A21,'Accident logs'!$F:$F,"Severe Accident") -> 0 | L21: =COUNTIFS('Accident logs'!$B:$B,$A21,'Accident logs'!$M:$M,"MRA") -> 0 | M21: =COUNTIFS('Accident logs'!$B:$B,$A21,'Accident logs'!$N:$N,"Fatality") -> 0 | N21: =COUNTIFS('Accident logs'!$B:$B,$A21,'Accident logs'!$F:$F,"LTA") -> 0 | O21: =$N21+$G21+$K21 -> 0 | P21: =SUMIFS($C:$C,$A:$A,">="&EDATE($A21,-11),$A:$A,"<="&$A21) -> 1391310 | Q21: =SUMIFS($D:$D,$A:$A,">="&EDATE($A21,-11),$A:$A,"<="&$A21) -> 0 | R21: =SUMIFS($E:$E,$A:$A,">="&EDATE($A21,-11),$A:$A,"<="&$A21) -> 13 | S21: =SUMIFS($F:$F,$A:$A,">="&EDATE($A21,-11),$A:$A,"<="&$A21) -> 9 | T21: =SUMIFS($G:$G,$A:$A,">="&EDATE($A21,-11),$A:$A,"<="&$A21) -> 10 | U21: =SUMIFS($H:$H,$A:$A,">="&EDATE($A21,-11),$A:$A,"<="&$A21) -> 0 | V21: =SUMIFS($I:$I,$A:$A,">="&EDATE($A21,-11),$A:$A,"<="&$A21) -> 0 | W21: =SUMIFS($J:$J,$A:$A,">="&EDATE($A21,-11),$A:$A,"<="&$A21) -> 0 | X21: =SUMIFS($K:$K,$A:$A,">="&EDATE($A21,-11),$A:$A,"<="&$A21) -> 1 | Y21: =SUMIFS($L:$L,$A:$A,">="&EDATE($A21,-11),$A:$A,"<="&$A21) -> 1 | Z21: =SUMIFS($N:$N,$A:$A,">="&EDATE($A21,-11),$A:$A,"<="&$A21) -> 0 | AA21: =$Z21+$T21+$X21 -> 11 | AB21: =IF($P21=0,0,$AA21*1000000/$P21) -> 7.9062179 | AC21: =IF($P21=0,0,($Z21+$X21)*1000000/$P21) -> 0.71874708 | AD21: =IF($P21=0,0,$Q21*1000/$P21) -> 0

Sheet H&S
A1: Concerned Month | B1: Mass-Briefings | C1: Training-Induction | D1: Task Specific Trainings | E1: Subcontractor Pre-QualificatIon H&S Meetings | F1: Production H&S Leadership Vists | G1: H&S Campaign | H1: H&S Awards | I1: H&S Audits | J1: Safety Alerts | K1: Mock Drill | L1: Stop & Go By H&S | M1: Stop & Go By Production
A2: 45931 | B2: 0 | C2: 125 | D2: 10 | E2: 2 | F2: 0 | G2: 1 | H2: 0 | I2: 0 | J2: 0 | K2: 1 | L2: 0 | M2: 0
A3: 45962 | B3: 0 | C3: 599 | D3: 84 | E3: 0 | F3: 4 | G3: 1 | H3: 0 | I3: 0 | J3: 0 | K3: 1 | L3: 2 | M3: 0
A4: 45992 | B4: 0 | C4: 488 | D4: 93 | E4: 0 | F4: 4 | G4: 1 | H4: 0 | I4: 0 | J4: 0 | K4: 1 | L4: 4 | M4: 1
A5: 46023 | B5: 0 | C5: 373 | D5: 209 | E5: 1 | F5: 6 | G5: 1 | H5: 0 | I5: 0 | J5: 0 | K5: 1 | L5: 2 | M5: 1
A6: 46054 | B6: 1 | C6: 303 | D6: 84 | E6: 0 | F6: 11 | G6: 1 | H6: 1 | I6: 0 | J6: 0 | K6: 1 | L6: 4 | M6: 5
A7: 46082 | B7: 0 | C7: 282 | D7: 66 | E7: 3 | F7: 12 | G7: 1 | H7: 0 | I7: 0 | J7: 0 | K7: 1 | L7: 10 | M7: 9
A8: 46113 | B8: 1 | C8: 443 | D8: 416 | E8: 3 | F8: 9 | G8: 1 | H8: 1 | I8: 0 | J8: 0 | K8: 3 | L8: 10 | M8: 6
A9: 46143 | B9: 1 | C9: 220 | D9: 336 | E9: 0 | F9: 4 | G9: 1 | H9: 1 | I9: 0 | J9: 0 | K9: 3 | L9: 6 | M9: 15
A10: 46174 | B10: 2 | C10: 136 | D10: 1360 | E10: 4 | F10: 1 | G10: 2 | H10: 0 | I10: 0 | J10: 1 | K10: 0 | L10: 4 | M10: 8
A11: 46204 | B11: 0 | C11: 0 | D11: 0 | E11: 0 | F11: 0 | G11: 0 | H11: 0 | I11: 0 | J11: 0 | K11: 0 | L11: 0 | M11: 0
A12: YTD | B12: =SUM(B2:B11) -> 5 | C12: =SUM(C2:C11) -> 2969 | D12: =SUM(D2:D11) -> 2658 | E12: =SUM(E2:E11) -> 13 | F12: =SUM(F2:F11) -> 51 | G12: =SUM(G2:G11) -> 10 | H12: =SUM(H2:H11) -> 3 | I12: =SUM(I2:I11) -> 0 | ... M12: =SUM(M2:M11) -> 45

Sheet Raw Data
B2: Zone | C2: ZONE'S | D2: KPI Metric | E2: TARGET | F2: January | G2: February | H2: March | I2: April | J2: May | K2: June | L2: July | M2: August | N2: September | O2: October | P2: November | Q2: December
B3: Zone CC | C3: ZONE CC | D3: Leadership Walkthroughs | E3: 2 | F3: 1 | G3: 7 | H3: 5 | I3: 1 | J3: 1 | K3: 1 | L3: 0 | M3: 0 | N3: 0 | O3: 0 | P3: 0 | Q3: 0
B4: Zone CC | D4: Stop&Go by H&S | F4: 0 | G4: 17 | H4: 10 | I4: 17 | J4: 0 | K4: 1 | L4: 0 | M4: 0 | N4: 0 | O4: 0 | P4: 0 | Q4: 0
B5: Zone CC | D5: Stop&Go by Production | F5: 0 | G5: 10 | H5: 9 | I5: 5 | J5: 0 | K5: 5 | L5: 0 | M5: 0 | N5: 0 | O5: 0 | P5: 0 | Q5: 0
B6: Zone CC | D6: Near Misses | F6: 1 | G6: 1 | H6: 0 | I6: 1 | J6: 1 | K6: 0 | L6: 0 | M6: 0 | N6: 0 | O6: 0 | P6: 0 | Q6: 0
B7: Zone CC | D7: Major Risk Near Misses | F7: 1 | G7: 1 | H7: 0 | I7: 1 | J7: 1 | K7: 0 | L7: 0 | M7: 0 | N7: 0 | O7: 0 | P7: 0 | Q7: 0
B8: Zone CC | D8: Property Damage | F8: 0 | G8: 0 | H8: 0 | I8: 0 | J8: 0 | K8: 0 | L8: 0 | M8: 0 | N8: 0 | O8: 0 | P8: 0 | Q8: 0
B9: Zone CC | D9: First Aid Cases | F9: 0 | G9: 1 | H9: 1 | I9: 1 | J9: 2 | K9: 2 | L9: 0 | M9: 0 | N9: 0 | O9: 0 | P9: 0 | Q9: 0
B10: Zone CC | D10: LTA (Lost Time Accident) | F10: 0 | G10: 0 | H10: 0 | I10: 0 | J10: 0 | K10: 0 | L10: 0 | M10: 0 | N10: 0 | O10: 0 | P10: 0 | Q10: 0
B11: Zone CC | D11: Major Risk Accident | F11: 0 | G11: 0 | H11: 0 | I11: 0 | J11: 0 | K11: 0 | L11: 0 | M11: 0 | N11: 0 | O11: 0 | P11: 0 | Q11: 0
B12: Zone CC | D12: Severe Accident | F12: 0 | G12: 0 | H12: 0 | I12: 0 | J12: 0 | K12: 0 | L12: 0 | M12: 0 | N12: 0 | O12: 0 | P12: 0 | Q12: 0
B13: Zone CC | D13: H&S Meetings Held | E13: 2 | F13: 2 | G13: 6 | H13: 4 | I13: 2 | J13: 3 | K13: 0 | L13: 0 | M13: 0 | N13: 0 | O13: 0 | P13: 0 | Q13: 0
B14: Zone CC | D14: Task Specific trainings | E14: 4 | F14: 2 | G14: 6 | H14: 4 | I14: 5 | J14: 9 | K14: 5 | L14: 0 | M14: 0 | N14: 0 | O14: 0 | P14: 0 | Q14: 0
B15: Zone CC | D15: TBT by Production Supervision | E15: 4 | F15: 1 | G15: 3 | H15: 3 | I15: 4 | J15: 4 | K15: 0 | L15: 0 | M15: 0 | N15: 0 | O15: 0 | P15: 0 | Q15: 0
B16: Zone CC | D16: Drills | E16: 1 | F16: 0 | G16: 1 | H16: 1 | I16: 1 | J16: 1 | K16: 0 | L16: 0 | M16: 0 | N16: 0 | O16: 0 | P16: 0 | Q16: 0
B17: Zone HPTC | C17: ZONE HPTC | D17: Leadership Walkthroughs | E17: 2 | F17: 1 | G17: 3 | H17: 3 | I17: 4 | J17: 2 | K17: 0 | L17: 0 | M17: 0 | N17: 0 | O17: 0 | P17: 0 | Q17: 0
B18: Zone HPTC | D18: Stop&Go by H&S | F18: 0 | G18: 5 | H18: 1 | I18: 2 | J18: 3 | K18: 0 | L18: 0 | M18: 0 | N18: 0 | O18: 0 | P18: 0 | Q18: 0
B19: Zone HPTC | D19: Stop&Go by Production | F19: 0 | G19: 2 | H19: 2 | I19: 12 | J19: 8 | K19: 3 | L19: 0 | M19: 0 | N19: 0 | O19: 0 | P19: 0 | Q19: 0
B20: Zone HPTC | D20: Near Misses | F20: 0 | G20: 1 | H20: 0 | I20: 0 | J20: 0 | K20: 0 | L20: 0 | M20: 0 | N20: 0 | O20: 0 | P20: 0 | Q20: 0
B21: Zone HPTC | D21: Major Risk Near Misses | F21: 0 | G21: 1 | H21: 0 | I21: 0 | J21: 0 | K21: 0 | L21: 0 | M21: 0 | N21: 0 | O21: 0 | P21: 0 | Q21: 0
B22: Zone HPTC | D22: Property Damage | F22: 0 | G22: 0 | H22: 0 | I22: 1 | J22: 0 | K22: 0 | L22: 0 | M22: 0 | N22: 0 | O22: 0 | P22: 0 | Q22: 0
B23: Zone HPTC | D23: First Aid Cases | F23: 0 | G23: 0 | H23: 0 | I23: 0 | J23: 0 | K23: 0 | L23: 0 | M23: 0 | N23: 0 | O23: 0 | P23: 0 | Q23: 0
B24: Zone HPTC | D24: LTA (Lost Time Accident) | F24: 0 | G24: 0 | H24: 0 | I24: 0 | J24: 0 | K24: 0 | L24: 0 | M24: 0 | N24: 0 | O24: 0 | P24: 0 | Q24: 0
B25: Zone HPTC | D25: Major Risk Accident | F25: 0 | G25: 0 | H25: 0 | I25: 0 | J25: 0 | K25: 0 | L25: 0 | M25: 0 | N25: 0 | O25: 0 | P25: 0 | Q25: 0
B26: Zone HPTC | D26: Severe Accident | F26: 0 | G26: 0 | H26: 0 | I26: 0 | J26: 0 | K26: 0 | L26: 0 | M26: 0 | N26: 0 | O26: 0 | P26: 0 | Q26: 0
B27: Zone HPTC | D27: H&S Meetings Held | E27: 2 | F27: 0 | G27: 5 | H27: 1 | I27: 3 | J27: 3 | K27: 0 | L27: 0 | M27: 0 | N27: 0 | O27: 0 | P27: 0 | Q27: 0
B28: Zone HPTC | D28: Task Specific trainings | E28: 4 | F28: 0 | G28: 2 | H28: 1 | I28: 3 | J28: 3 | K28: 4 | L28: 0 | M28: 0 | N28: 0 | O28: 0 | P28: 0 | Q28: 0
B29: Zone HPTC | D29: TBT by Production Supervision | E29: 4 | F29: 0 | G29: 1 | H29: 1 | I29: 0 | J29: 4 | K29: 0 | L29: 0 | M29: 0 | N29: 0 | O29: 0 | P29: 0 | Q29: 0
B30: Zone HPTC | D30: Drills | E30: 1 | F30: 0 | G30: 0 | H30: 1 | I30: 1 | J30: 1 | K30: 0 | L30: 0 | M30: 0 | N30: 0 | O30: 0 | P30: 0 | Q30: 0
B31: Zone CT1 / CT2 | C31: Zone CT1/CT2 | D31: Leadership Walkthroughs | E31: 2 | F31: 0 | G31: 1 | H31: 1 | I31: 2 | J31: 1 | K31: 0 | L31: 0 | M31: 0 | N31: 0 | O31: 0 | P31: 0 | Q31: 0
B32: Zone CT1 / CT2 | D32: Stop&Go by H&S | F32: 0 | G32: 1 | H32: 0 | I32: 4 | J32: 0 | K32: 3 | L32: 0 | M32: 0 | N32: 0 | O32: 0 | P32: 0 | Q32: 0
B33: Zone CT1 / CT2 | D33: Stop&Go by Production | F33: 0 | G33: 0 | H33: 0 | I33: 0 | J33: 0 | K33: 0 | L33: 0 | M33: 0 | N33: 0 | O33: 0 | P33: 0 | Q33: 0
B34: Zone CT1 / CT2 | D34: Near Misses | F34: 0 | G34: 0 | H34: 0 | I34: 0 | J34: 0 | K34: 0 | L34: 0 | M34: 0 | N34: 0 | O34: 0 | P34: 0 | Q34: 0
B35: Zone CT1 / CT2 | D35: Major Risk Near Misses | F35: 0 | G35: 0 | H35: 0 | I35: 0 | J35: 0 | K35: 0 | L35: 0 | M35: 0 | N35: 0 | O35: 0 | P35: 0 | Q35: 0
B36: Zone CT1 / CT2 | D36: Property Damage | F36: 0 | G36: 0 | H36: 0 | I36: 0 | J36: 0 | K36: 0 | L36: 0 | M36: 0 | N36: 0 | O36: 0 | P36: 0 | Q36: 0
B37: Zone CT1 / CT2 | D37: First Aid Cases | F37: 0 | G37: 0 | H37: 0 | I37: 0 | J37: 0 | K37: 0 | L37: 0 | M37: 0 | N37: 0 | O37: 0 | P37: 0 | Q37: 0
B38: Zone CT1 / CT2 | D38: LTA (Lost Time Accident) | F38: 0 | G38: 0 | H38: 0 | I38: 0 | J38: 0 | K38: 0 | L38: 0 | M38: 0 | N38: 0 | O38: 0 | P38: 0 | Q38: 0
B39: Zone CT1 / CT2 | D39: Major Risk Accident | F39: 0 | G39: 0 | H39: 0 | I39: 0 | J39: 0 | K39: 0 | L39: 0 | M39: 0 | N39: 0 | O39: 0 | P39: 0 | Q39: 0
B40: Zone CT1 / CT2 | D40: Severe Accident | F40: 0 | G40: 0 | H40: 0 | I40: 0 | J40: 0 | K40: 0 | L40: 0 | M40: 0 | N40: 0 | O40: 0 | P40: 0 | Q40: 0
B41: Zone CT1 / CT2 | D41: H&S Meetings Held | E41: 2 | F41: 0 | G41: 0 | H41: 1 | I41: 3 | J41: 4 | K41: 0 | L41: 0 | M41: 0 | N41: 0 | O41: 0 | P41: 0 | Q41: 0
...

Sheet Accident logs
A1: Incident Date | B1: Month | C1: Time | D1: Reported By | E1: What Happened | F1: Primary Category | G1: Population | H1: Zone / Area | I1: Major risks (If Any) | J1: Employee Full Name | K1: DaysLost | L1: Immediate actions taken | M1: Event severity | N1: Classification [Incident]
A2: 45997 | B2: =IF($A2="","",DATE(YEAR($A2),MONTH($A2),1)) -> 45992 | D2: Gozel, Amiri | E2: A worker reported sudden pain and swelling in his foot during working hours. Upon receiving the information, he was immediately escorted to the BBIAGC Site Clinic, where he received first aid treatment. | F2: First Aid | H2: Central Court | I2: Not Applicable | K2: 0 | N2: First Aid Case
A3: 46007 | B3: =IF($A3="","",DATE(YEAR($A3),MONTH($A3),1)) -> 45992 | D3: Gozel, Amiri | E3: A Near Miss case occurred during the installation of a tower crane. A ladder slipped from the hands of an installer during reinstallation. After installing the main structure, the installers discovered that the ladder had been installed incorrectly, so they decided to reinstall it on site. According to the safe work procedures, the ladder must be secured to the main beam of the tower crane on the ground. | F3: Near Miss | H3: Central Court | I3: Work At Height | K3: 0 | M3: MRN | N3: Not Applicable
A4: 46049 | B4: =IF($A4="","",DATE(YEAR($A4),MONTH($A4),1)) -> 46023 | D4: Gozel, Amiri | E4: The Shoring materials (T60) delivered on site in unstable conditions, the materials were stacked on a flatbed trailer without adequate stability, During the unhooking of the trailer belt straps used to secure the load, a near miss incident occurred. Due to the unstable stacking. No injuries were reported. | F4: Near Miss | H4: Central Court | I4: Stability | K4: 0 | M4: MRN | N4: Not Applicable
A5: 46063 | B5: =IF($A5="","",DATE(YEAR($A5),MONTH($A5),1)) -> 46054 | D5: Gozel, Amiri | E5: Work was on-going to install a new water station in the CC area. There was difficulty pushing the water tank into its correct position inside the station, a sharp edge was present and was not identified or protected during the fabrication stage. While pushing the water line/tank with force, the worker’s finger was Pinched in between the structure and water tank, causing a finger injury. | F5: First Aid | H5: Central Court | I5: Not Applicable | K5: 0 | N5: First Aid Case
A6: 46063 | B6: =IF($A6="","",DATE(YEAR($A6),MONTH($A6),1)) -> 46054 | D6: Gozel, Amiri | E6: During ground leveling and compacting by skid loader the skid loader damage underground live cable going to BAUER Temporary office coming from Panel board, there is no signages stand of cables direction. | F6: Near Miss | H6: CT2 | I6: Hazardous Energies | K6: 0 | M6: MRN | N6: Not Applicable
A7: 46068 | B7: =IF($A7="","",DATE(YEAR($A7),MONTH($A7),1)) -> 46054 | D7: Gozel, Amiri | E7: At approximately 20:00 hrs at HPTC, adjacent to TC06, the lights of Tower Crane 06 suddenly went off. Upon arrival, the site team observed a melting odor emanating from the electrical panel connected to TC06. | F7: Near Miss | H7: HPTC | I7: Hazardous Energies | K7: 0 | M7: MRN | N7: Not Applicable
A8: 46076 | B8: =IF($A8="","",DATE(YEAR($A8),MONTH($A8),1)) -> 46054 | D8: Gozel, Amiri | E8: While the Rigger was performing his duties of signaling the lifting of the shutter by the tower crane, he was standing on top of the rebar cage. As he descended from the Rebar cage, his leg struck the sharp end of the Rebar, resulting in an injury of his left leg | F8: First Aid | H8: Central Court | I8: Not Applicable | K8: 0 | N8: First Aid Case
A9: 46079 | B9: =IF($A9="","",DATE(YEAR($A9),MONTH($A9),1)) -> 46054 | D9: Gozel, Amiri | E9: while unloading of Concrete Slab, by doing so, during the swing of load suddenly the load gets unstable then the Boom Truck Operator lowered the boom, and the load hits the Boom Truck and fall in the ground. | F9: Near Miss | H9: Central Court | I9: Lifting | K9: 0 | M9: MRN | N9: Not Applicable
A10: 46106 | B10: =IF($A10="","",DATE(YEAR($A10),MONTH($A10),1)) -> 46082 | D10: Gozel, Amiri | E10: During steel-cutting activities at the JV steel yard, a steel fixer was arranging the cut steel when he was injured (Cut) by the sharp edge of the steel on his left hand’s index finger. | F10: First Aid | H10: Central Court | I10: Not Applicable | K10: 0 | N10: First Aid Case
A11: 46107 | B11: =IF($A11="","",DATE(YEAR($A11),MONTH($A11),1)) -> 46082 | D11: Gozel, Amiri | E11: The worker sustained a puncture wound to the sole of the right foot after stepping on a nail during work activities. | F11: First Aid | H11: Central Court | I11: Not Applicable | K11: 0 | N11: First Aid Case
A12: 46116 | B12: =IF($A12="","",DATE(YEAR($A12),MONTH($A12),1)) -> 46113 | D12: Gozel, Amiri | E12: During the unloading of rebar, a sudden wind gust caused the load to swing while the Zoomlion ZTC550V was in operation. Despite the crane's stability systems, the operator failed to take the necessary corrective action—specifically failing to "boom down" to stabilize the load. Consequently, the swinging rebar struck the crane, resulting in shattered operator cabin glass. This was the first operational task for this recently hired crane and operator. | F12: Near Miss | H12: HPTC | I12: Lifting | K12: 0 | M12: MRN | N12: Not Applicable
A13: 46117 | B13: =IF($A13="","",DATE(YEAR($A13),MONTH($A13),1)) -> 46113 | D13: Gozel, Amiri | E13: During a routine daily safety inspection, a jack support failed and fell from height, landing in the immediate vicinity of the safety engineer. This event is classified as a Major Risk Near Miss, as the weight and trajectory of the falling object had the potential to cause fatal or life-altering injuries to personnel. Fortunately, no contact occurred. | F13: Near Miss | H13: Central Court | I13: Stability | K13: 0 | M13: MRN | N13: Not Applicable
A14: 46119 | B14: =IF($A14="","",DATE(YEAR($A14),MONTH($A14),1)) -> 46113 | D14: Gozel, Amiri | E14: IP removed reinforcing steel (rebar) for short cut. During this action, he lost control while pushing the rebar, which caused it to strike and caused a minor injury in his forehead. | F14: First Aid | H14: Central Court | I14: Not Applicable | K14: 0 | M14: Not Applicable | N14: First Aid Case
A15: 46133 | B15: =IF($A15="","",DATE(YEAR($A15),MONTH($A15),1)) -> 46113 | D15: Gozel, Amiri | E15: On 21.04.2026 around 17:00 am, at CC Zone, during pouring the concrete pump line was observed leaking from the pipeline connection, and a section of the pipe was found damaged and in unsafe operating condition. The equipment showed signs of poor maintenance, creating a risk of concrete spillage, pressure failure, hose whipping, and potential injury to personnel working nearby. | F15: Near Miss | H15: Central Court | I15: Not Applicable | K15: 0 | M15: Not Applicable | N15: Not Applicable
A16: 46135 | B16: =IF($A16="","",DATE(YEAR($A16),MONTH($A16),1)) -> 46113 | D16: Gozel, Amiri | E16: A near miss incident occurred during manual steel fabrication works. While handling materials manually, a steel piece slipped from the worker’s hand due to vertical handling and fell through a small opening into the core area. The activity was being performed manually without adequate control measures, creating a risk of falling objects and potential injury to personnel below. | F16: Near Miss | H16: Central Court | I16: Work At Height | K16: 0 | M16: MRN | N16: Not Applicable
A17: 46145 | B17: =IF($A17="","",DATE(YEAR($A17),MONTH($A17),1)) -> 46143 | D17: Gozel, Amiri | E17: There was cardboard under the battery box. Because of the heat, the cardboard starts burning | F17: Near Miss | H17: Central Court | I17: Hazardous Energies | K17: 0 | M17: MRN | N17: Not Applicable
A18: 46148 | B18: =IF($A18="","",DATE(YEAR($A18),MONTH($A18),1)) -> 46143 | D18: Gozel, Amiri | E18: While a BRC scaffolding operative was manually passing a bracing member upward to a formworker on the slab level, the component slipped from his hand. An Annaq operative was walking along the designated path immediately adjacent to the scaffold at that moment. The falling bracing touched the Annaq worker's safety helmet, deflected away from his shoulder, and landed on the ground. | F18: Near Miss | H18: Central Court | I18: Not Applicable | K18: 0 | M18: Not Applicable | N18: Not Applicable
A19: 46153 | B19: =IF($A19="","",DATE(YEAR($A19),MONTH($A19),1)) -> 46143 | D19: Gozel, Amiri | E19: A First Aid case occurred at CC Zone 2 involving a worker suffering from heat-related distress. The worker experienced dizziness and physical exhaustion due to high thermal conditions. Prompt intervention by colleagues and the Site Engineer ensured the worker received water and medical transport to the clinic for treatment. Following a thorough examination at the clinic, the attending physician confirmed that the symptoms were a direct result of dehydration | F19: First Aid | H19: Central Court | I19: Not Applicable | K19: 0 | M19: Not Applicable | N19: First Aid Case
A20: 46156 | B20: =IF($A20="","",DATE(YEAR($A20),MONTH($A20),1)) -> 46143 | D20: Gozel, Amiri | E20: On 13.05.2026 at around 15:00 truck arrives at JV laydown to deliver steel due to no mobile crane available the truck waited at laydown area till 02:00 14.05.2026 when the truck taking maneuver for reverse parking for unloading the materials, by doing so there’s was no Flag man available during the equipment movement and the truck driver could see clearly the material stocked on his back because of the poor illumination, while he was reversing he hits the materials, no injuries , no materials damages recorded nor equipment damage. | F20: Near Miss | H20: LAYDOWN | I20: Not Applicable | K20: 0 | M20: Not Applicable | N20: Not Applicable
A21: 46157 | B21: =IF($A21="","",DATE(YEAR($A21),MONTH($A21),1)) -> 46143 | D21: Gozel, Amiri | E21: On 15.05.2026 at 09:45, a First Aid case occurred at CC Zone 4. During routine site activity, a worker experienced dizziness and discomfort due to excessive heat exposure while performing assigned tasks on site. The worker immediately informed his colleague that he was not feeling well. The colleague took him to the nearest store where he could get the shade. Then immediately called the Ambulance.Upon arrival at the clinic, we bought the worker to clinic from ambulance and did the routine check-up the Blood Pressure & pulse rate were observed normal. | F21: First Aid | H21: Central Court | I21: Not Applicable | K21: 0 | M21: Not Applicable | N21: First Aid Case
A22: 46158 | B22: =IF($A22="","",DATE(YEAR($A22),MONTH($A22),1)) -> 46143 | D22: Gozel, Amiri | E22: On 16 May,2026 at around 10:02, during de-shuttering activity, an clip/material component fell to the ground from the working platform within 2,5m height. No injuries was identified | F22: Near Miss | H22: Central Court | I22: Not Applicable | K22: 0 | M22: Not Applicable | N22: Not Applicable
A23: 46172 | B23: =IF($A23="","",DATE(YEAR($A23),MONTH($A23),1)) -> 46143 | D23: Abdullah Albin, SAAD | E23: On 30 May 2026 at around 19:55, a fatal incident was reported at the project site. De-shuttering activities were in progress at Core 2, and shuttering materials were being lifted to the TC-01 Storage area. During the lifting operation, two workers were manually handling and holding a shutter panel. While the shutter was being moved, it suddenly swung unexpectedly, causing it to strike one of the workers in the neck area. The worker hit with scaffolding and died on the spot. | F23: Severe Accident | H23: Central Court | I23: Lifting | K23: 0 | M23: MRA | N23: Fatality
A24: 46201 | B24: =IF($A24="","",DATE(YEAR($A24),MONTH($A24),1)) -> 46174 | D24: Gozel, Amiri | E24: On June 28, 2026, at approximately 01:36 AM, during the site reopening mass briefing, a BRC employee experienced nauseous and got unconscious. The briefing was immediately paused to prioritize the worker's safety. Site medical personnel were notified, and the employee was escorted to the site clinic for evaluation. The mass briefing was safely concluded following the worker's transfer to the medical facility. Upon arrival at the site clinic, the worker’s vital signs were checked. His blood pressure and pulse rate were elevated, registering at 138/65 mmHg. First aid protocols were initiated. After the initial nursing examination, patient have sinus bradycardia. (Heart rate less than 50 bpm).The patient's condition is stable. Advise visit hospital for further treatment. | F24: First Aid | G24: BRC | H24: Central Court | I24: Not Applicable | K24: 0 | M24: Not Applicable | N24: First Aid Case
A25: 46201 | B25: =IF($A25="","",DATE(YEAR($A25),MONTH($A25),1)) -> 46174 | D25: Gozel, Amiri | E25: On June 28, 2026, at approximately 07:45 AM, during the site reopening mass briefing, a BRC employee experienced sudden dizziness and lay down on the ground. The briefing was immediately paused to prioritize the worker's safety. Site medical personnel were notified, and the employee was escorted to the site clinic for evaluation. The mass briefing was safely concluded following the worker's transfer to the medical facility. Upon arrival at the site clinic, the worker’s vital signs were checked. His blood pressure and pulse rate were elevated, registering at 152/89 mmHg. First aid protocols were initiated. The worker is currently resting and remains under medical observation at the clinic until his vitals stabilize. | F25: First Aid | G25: BRC | H25: Central Court | I25: Not Applicable | K25: 0 | M25: Not Applicable | N25: First Aid Case

Sheet Leadership Inspection 2026
B1: QNTC LEADERSHIP SAFETY INSPECTION MATRIX 2026
B2: Project Name | C2: Who | D2: Jan | F2: Feb | H2: Mar | J2: Apr | L2: May | N2: Jun | P2: Jul | R2: Aug | T2: Sep | V2: Oct | X2: Nov | Z2: Dec
D3: Planned | E3: Completed | F3: Planned | G3: Completed | H3: Planned | I3: Completed | J3: Planned | K3: Completed | L3: Planned | M3: Completed | N3: Planned | O3: Completed | P3: Planned | Q3: Completed | R3: Planned | S3: Completed | T3: Planned | U3: Completed | V3: Planned | W3: Completed | X3: Planned | Y3: Completed | Z3: Planned | AA3: Completed
B4: QNTC | C4: FSY | F4: 0 | G4: 1 | L4: 0 | R4: 0 | X4: 0
C5: FFE | D5: 0 | E5: 1 | H5: 0 | I5: 1 | L5: 0 | P5: 0 | T5: 0 | X5: 0
C6: AEJ | F6: 0 | G6: 1 | J6: 0 | K6: 1 | N6: 0 | R6: 0 | V6: 0 | Z6: 0
C7: SLE | D7: 0 | E7: 1 | H7: 0 | I7: 1 | N7: 0 | T7: 0 | X7: 0
C8: GBI | D8: 0 | E8: 1 | F8: 0 | G8: 1 | J8: 0 | K8: 1 | P8: 0 | V8: 0 | Z8: 0
C9: BGO | P9: 0 | T9: 0 | X9: 0
C10: RKO | L10: 0 | R10: 0 | V10: 0 | Z10: 0
C11: JVG | N11: 0 | P11: 0 | T11: 0 | X11: 0
C12: JCH | N12: 0 | R12: 0 | V12: 0 | Z12: 0
C13: AHY | F13: 0 | G13: 1 | J13: 0 | K13: 1 | N13: 0 | R13: 0 | V13: 0 | Z13: 0
C14: NPR | P14: 0 | T14: 0 | X14: 0
C15: PAV | N15: 0 | R15: 0 | V15: 0 | Z15: 0
C16: DDA | P16: 0 | T16: 0 | X16: 0
C18: PLANNED | D18: {=SUMPRODUCT((LEN(D4:D16)-LEN(SUBSTITUTE(D4:D16, ",", ""))+1)*(D4:D16<>""))} -> 3 | F18: {=SUMPRODUCT((LEN(F4:F16)-LEN(SUBSTITUTE(F4:F16, ",", ""))+1)*(F4:F16<>""))} -> 4 | H18: {=SUMPRODUCT((LEN(H4:H16)-LEN(SUBSTITUTE(H4:H16, ",", ""))+1)*(H4:H16<>""))} -> 2 | J18: {=SUMPRODUCT((LEN(J4:J16)-LEN(SUBSTITUTE(J4:J16, ",", ""))+1)*(J4:J16<>""))} -> 3 | L18: {=SUMPRODUCT((LEN(L4:L16)-LEN(SUBSTITUTE(L4:L16, ",", ""))+1)*(L4:L16<>""))} -> 3 | N18: {=SUMPRODUCT((LEN(N4:N16)-LEN(SUBSTITUTE(N4:N16, ",", ""))+1)*(N4:N16<>""))} -> 6 | P18: {=SUMPRODUCT((LEN(P4:P16)-LEN(SUBSTITUTE(P4:P16, ",", ""))+1)*(P4:P16<>""))} -> 6 | R18: {=SUMPRODUCT((LEN(R4:R16)-LEN(SUBSTITUTE(R4:R16, ",", ""))+1)*(R4:R16<>""))} -> 6 | T18: {=SUMPRODUCT((LEN(T4:T16)-LEN(SUBSTITUTE(T4:T16, ",", ""))+1)*(T4:T16<>""))} -> 6 | V18: {=SUMPRODUCT((LEN(V4:V16)-LEN(SUBSTITUTE(V4:V16, ",", ""))+1)*(V4:V16<>""))} -> 6 | X18: {=SUMPRODUCT((LEN(X4:X16)-LEN(SUBSTITUTE(X4:X16, ",", ""))+1)*(X4:X16<>""))} -> 7 | Z18: {=SUMPRODUCT((LEN(Z4:Z16)-LEN(SUBSTITUTE(Z4:Z16, ",", ""))+1)*(Z4:Z16<>""))} -> 6 | AB18: =SUM(D18:Z18) -> 58
C19: KEY COMPLETED | D19: {=SUMPRODUCT((LEN(E4:E16)-LEN(SUBSTITUTE(E4:E16, ",", ""))+1)*(E4:E16<>""))} -> 3 | F19: {=SUMPRODUCT((LEN(G4:G16)-LEN(SUBSTITUTE(G4:G16, ",", ""))+1)*(G4:G16<>""))} -> 4 | H19: {=SUMPRODUCT((LEN(I4:I16)-LEN(SUBSTITUTE(I4:I16, ",", ""))+1)*(I4:I16<>""))} -> 2 | J19: {=SUMPRODUCT((LEN(K4:K16)-LEN(SUBSTITUTE(K4:K16, ",", ""))+1)*(K4:K16<>""))} -> 3 | L19: {=SUMPRODUCT((LEN(M4:M16)-LEN(SUBSTITUTE(M4:M16, ",", ""))+1)*(M4:M16<>""))} -> 0 | N19: {=SUMPRODUCT((LEN(O4:O16)-LEN(SUBSTITUTE(O4:O16, ",", ""))+1)*(O4:O16<>""))} -> 0 | P19: {=SUMPRODUCT((LEN(Q4:Q16)-LEN(SUBSTITUTE(Q4:Q16, ",", ""))+1)*(Q4:Q16<>""))} -> 0 | R19: {=SUMPRODUCT((LEN(S4:S16)-LEN(SUBSTITUTE(S4:S16, ",", ""))+1)*(S4:S16<>""))} -> 0 | T19: {=SUMPRODUCT((LEN(U4:U16)-LEN(SUBSTITUTE(U4:U16, ",", ""))+1)*(U4:U16<>""))} -> 0 | V19: {=SUMPRODUCT((LEN(W4:W16)-LEN(SUBSTITUTE(W4:W16, ",", ""))+1)*(W4:W16<>""))} -> 0 | X19: {=SUMPRODUCT((LEN(Y4:Y16)-LEN(SUBSTITUTE(Y4:Y16, ",", ""))+1)*(Y4:Y16<>""))} -> 0 | Z19: {=SUMPRODUCT((LEN(AA4:AA16)-LEN(SUBSTITUTE(AA4:AA16, ",", ""))+1)*(AA4:AA16<>""))} -> 0 | AB19: =SUM(D19:Z19) -> 12
C20: NOT COMPLETE | D20: =IF(D18=0,0,IF(OR(ISBLANK(D18),ISBLANK(D19)),0,(D18-D19)/D18*100))/100 -> 0 | F20: =IF(F18=0,0,IF(OR(ISBLANK(F18),ISBLANK(F19)),0,(F18-F19)/F18*100))/100 -> 0 | H20: =IF(H18=0,0,IF(OR(ISBLANK(H18),ISBLANK(H19)),0,(H18-H19)/H18*100))/100 -> 0 | J20: =IF(J18=0,0,IF(OR(ISBLANK(J18),ISBLANK(J19)),0,(J18-J19)/J18*100))/100 -> 0 | L20: =IF(L18=0,0,IF(OR(ISBLANK(L18),ISBLANK(L19)),0,(L18-L19)/L18*100))/100 -> 1 | N20: =IF(N18=0,0,IF(OR(ISBLANK(N18),ISBLANK(N19)),0,(N18-N19)/N18*100))/100 -> 1 | P20: =IF(P18=0,0,IF(OR(ISBLANK(P18),ISBLANK(P19)),0,(P18-P19)/P18*100))/100 -> 1 | R20: =IF(R18=0,0,IF(OR(ISBLANK(R18),ISBLANK(R19)),0,(R18-R19)/R18*100))/100 -> 1 | T20: =IF(T18=0,0,IF(OR(ISBLANK(T18),ISBLANK(T19)),0,(T18-T19)/T18*100))/100 -> 1 | V20: =IF(V18=0,0,IF(OR(ISBLANK(V18),ISBLANK(V19)),0,(V18-V19)/V18*100))/100 -> 1 | X20: =IF(X18=0,0,IF(OR(ISBLANK(X18),ISBLANK(X19)),0,(X18-X19)/X18*100))/100 -> 1 | Z20: =IF(Z18=0,0,IF(OR(ISBLANK(Z18),ISBLANK(Z19)),0,(Z18-Z19)/Z18*100))/100 -> 1
C21: NOT COMPLETE | D21: =D18-D19 -> 0 | F21: =F18-F19 -> 0 | H21: =H18-H19 -> 0 | J21: =J18-J19 -> 0 | L21: =L18-L19 -> 3 | N21: =N18-N19 -> 6 | P21: =P18-P19 -> 6 | R21: =R18-R19 -> 6 | T21: =T18-T19 -> 6 | V21: =V18-V19 -> 6 | X21: =X18-X19 -> 7 | Z21: =Z18-Z19 -> 6
B23: Abbreviations | E23: Attendees
B24: FSY | C24: Francois SYLVESTRE | E24: FFE or AEJ, SLE, GBI, NPR, BGO, Maksim Y, others upon request
B25: FFE | C25: Frederic FERRE | E25: SLE, GBI, NPR, BGO, Eric M, Maksim Y, others upon request
B26: AEJ | C26: Ayad ElJammal | E26: SLE, GBI, NPR, BGO, Eric M, Maksim Y, others upon request
B27: SLE | C27: Stephane LEVENARD | E27: Package and Zone Supervision, others upon request
B28: GBI | C28: Geoffroy BIETH | E28: Package and Zone Supervision, others upon request
B29: NPR | C29: Nicolas PROGREBNOI | E29: Package and Zone Supervision, others upon request
B30: RKO | C30: Richard KOENIG | E30: Package and Zone Supervision, others upon request
B31: JVG | C31: Jean Vianney GARD | E31: Package and Zone Supervision, others upon request
B32: JCH | C32: Joey CHAMI | E32: Package and Zone Supervision, others upon request
B33: PAV | C33: Patrizio AVARO | E33: Package and Zone Supervision, others upon request
B34: DDA | C34: David DAMBREVILLE | E34: Package and Zone Supervision, others upon request
B35: AHY | C35: AntoineYAGHMOUR | E35: Package and Zone Supervision, others upon request
B36: BGO | C36: Bruno GONCALVES | E36: Package and Zone Supervision, others upon request

Sheet Violations
A1: SN | B1: Iqama No. | C1: Name | D1: Company | E1: Location | F1: Violation Type | G1: Category | H1: Date | I1: Month | J1: Disciplinary Action | K1: Status | L1: Count | M1: Reported By | N1: Remarks
A2: =IF($B2="","",COUNTA($B$2:$B2)) -> 1 | B2: 2627239426 | C2: Shahid Ali | D2: ELITE HEART | E2: HPTC | F2: False Work at Height Procedure | G2: Minor | H2: 46086 | I2: =IF($H2="","",DATE(YEAR($H2),MONTH($H2),1)) -> 46082 | J2: 1st Warning | K2: Closed | L2: 1 | M2: Parahat DURDYYEV | N2: Not following Work at Height requirements
A3: =IF($B3="","",COUNTA($B$2:$B3)) -> 2 | B3: 2533628315 | C3: Badshah Rawiz | D3: ELITE HEART | E3: HPTC | F3: Working on Incomplete Scaffolding | G3: Minor | H3: 46098 | I3: =IF($H3="","",DATE(YEAR($H3),MONTH($H3),1)) -> 46082 | J3: 1st Warning | K3: Closed | L3: 1 | M3: Pratyush MUDBHARI | N3: Not following Work at Height requirements
A4: =IF($B4="","",COUNTA($B$2:$B4)) -> 3 | B4: 2578331528 | C4: Ansur | D4: ELITE HEART | E4: HPTC | F4: Not Using Proper Acess | G4: Minor | H4: 46147 | I4: =IF($H4="","",DATE(YEAR($H4),MONTH($H4),1)) -> 46143 | J4: 1st Warning | K4: Closed | L4: 1 | M4: Rashed ALBLUEY | N4: Not following Work at Height requirements
A5: =IF($B5="","",COUNTA($B$2:$B5)) -> 4 | B5: 2578331445 | C5: Pinto | D5: ELITE HEART | E5: HPTC | F5: Not Using Proper Acess | G5: Minor | H5: 46147 | I5: =IF($H5="","",DATE(YEAR($H5),MONTH($H5),1)) -> 46143 | J5: 1st Warning | K5: Closed | L5: 1 | M5: Rashed ALBLUEY | N5: Not following Work at Height requirements
A6: =IF($B6="","",COUNTA($B$2:$B6)) -> 5 | B6: 2516097397 | C6: Raza Khan | D6: ELITE HEART | E6: HPTC | F6: Performing Prayer at Site in Working Area | G6: Minor | H6: 46152 | I6: =IF($H6="","",DATE(YEAR($H6),MONTH($H6),1)) -> 46143 | J6: 1st Warning | K6: Closed | L6: 1 | M6: Usama Shahid BUTT | N6: Any unsafe acts/practices to be determined by the HSE Department
A7: =IF($B7="","",COUNTA($B$2:$B7)) -> 6 | B7: 2420270973 | C7: Jawahar singh | D7: ELITE HEART | E7: HPTC | F7: Not Respecting Safety Personnel | G7: Minor | H7: 46153 | I7: =IF($H7="","",DATE(YEAR($H7),MONTH($H7),1)) -> 46143 | J7: 1st Warning | K7: Closed | L7: 1 | M7: Parahat DURDYYEV | N7: Any unsafe acts/practices to be determined by the HSE Department
A8: =IF($B8="","",COUNTA($B$2:$B8)) -> 7 | B8: 2579458973 | C8: Asif | D8: ELITE HEART | E8: HPTC | F8: Walking Near the excavation edge without the proper edge protextion on safe access | G8: Minor | H8: 46155 | I8: =IF($H8="","",DATE(YEAR($H8),MONTH($H8),1)) -> 46143 | J8: 1st Warning | K8: Closed | L8: 1 | M8: Prabhu MUTHU | N8: Not following Project HSE procedures
A9: =IF($B9="","",COUNTA($B$2:$B9)) -> 8 | B9: 2618183087 | C9: Syed Arshid | D9: BUILDING ROOTS | E9: Central Court | F9: Using improper way of Working at Height | G9: Minor | H9: 46158 | I9: =IF($H9="","",DATE(YEAR($H9),MONTH($H9),1)) -> 46143 | J9: 1st Warning | K9: Closed | L9: 1 | M9: Gurbanov ATAGELDI | N9: Not following Work at Height requirements
A10: =IF($B10="","",COUNTA($B$2:$B10)) -> 9 | B10: 2505154716 | C10: Raad Saleh Naji | D10: BUILDING ROOTS | E10: Central Court | F10: Unsafe Working platfom climbing between shoring towers | G10: Minor | H10: 46158 | I10: =IF($H10="","",DATE(YEAR($H10),MONTH($H10),1)) -> 46143 | J10: 1st Warning | K10: Closed | L10: 1 | M10: Lekhanath BOHORA | N10: Not following Work at Height requirements
A11: =IF($B11="","",COUNTA($B$2:$B11)) -> 10 | B11: 2564045322 | C11: Sana ullah | D11: BUILDING ROOTS | E11: Central Court | F11: Using improper way of Working at Height | G11: Minor | H11: 46158 | I11: =IF($H11="","",DATE(YEAR($H11),MONTH($H11),1)) -> 46143 | J11: 1st Warning | K11: Closed | L11: 1 | M11: Gurbanov ATAGELDI | N11: Not following Work at Height requirements
A12: =IF($B12="","",COUNTA($B$2:$B12)) -> 11 | B12: 2256674108 | C12: Fares Hazaea Abdulwasea | D12: BUILDING ROOTS | E12: Central Court | F12: Using improper way of Working at Height | G12: Minor | H12: 46158 | I12: =IF($H12="","",DATE(YEAR($H12),MONTH($H12),1)) -> 46143 | J12: 1st Warning | K12: Closed | L12: 1 | M12: Omar SALEH | N12: Not following Work at Height requirements
A13: =IF($B13="","",COUNTA($B$2:$B13)) -> 12 | B13: 2401491671 | C13: Alamzaib Khan | D13: ELITE HEART | E13: HPTC | F13: Working on Incomplete Scaffolding | G13: Minor | H13: 46159 | I13: =IF($H13="","",DATE(YEAR($H13),MONTH($H13),1)) -> 46143 | J13: 1st Warning | K13: Closed | L13: 1 | M13: Pratyush MUDBHARI | N13: Not following Work at Height requirements
... A31: =IF($B31="","",COUNTA($B$2:$B31)) -> 30 | B31: 2586386303 | C31: Abdul Hameed | D31: BUILDING ROOTS | E31: Central Court | F31: Climbing in the Steel Cage | G31: Major | H31: 46167 | I31: =IF($H31="","",DATE(YEAR($H31),MONTH($H31),1)) -> 46143 | J31: 1st Warning | K31: Closed | L31: 1 | M31: Usama Shahid BUTT | N31: Not following Project HSE procedures
